Workbook
Name Catastrophic: HeatMap!$G$20
Name High: HeatMap!$D$19
Name Impact: HeatMap!$F$21:$G$25
Name Likelihood: HeatMap!$C$21:$D$25
Name Low: HeatMap!$D$17
Name Medium: HeatMap!$D$18
Name Moderate: HeatMap!$G$18
Name Negligible: HeatMap!$G$16
Name riskassessment: Main!#REF!
Name Significant: HeatMap!$G$19
Name Very_High: HeatMap!$D$20
Name Very_Low: HeatMap!$D$16

Sheet Main
B1: RISK AND CONTROL ASSESSMENT TEMPLATE
A2: Client: | D2: Assessment period: | J2: Assessor: | N2: Approved by:
S3: Post Action Risk Assessment
D4: Risk | E4: Original assessment | K4: Controls | S4: Adjusted assessment
A5: Business Objective | B5: Main process | C5: Sub process | D5: Key risk and factors | E5: Likelihood | F5: Impact | G5: Key/Secondary | H5: Risk Category | I5: Data Frequency | J5: Mitigating controls | K5: Nature | L5: Responsibility | M5: Frequency | N5: Evidence | O5: Authoriser | P5: Auditors Recommended Action Plan | Q5: Responsible Person | R5: Agreed Date | S5: Likelihood | T5: Impact | U5: Improbable | V5: 1 | W5: Negligible | X5: 1 | Y5: Link to Dashboard
A6: Shareholder returns | B6: Finance, Investments and Treasury management | C6: Share price forecast | D6: Negative returns on the share price | E6: Very High | F6: Catastrophic | G6: Key risk | H6: Strategic Risk | I6: Time Series | J6: Effective hedging | K6: Preventive | M6: Daily | N6: Committe or Board decision | S6: Medium | T6: Moderate | U6: Low | V6: 2 | W6: Lower | X6: 2
D7: Unfavourable exchange rate | E7: Probable | F7: Catastrophic | G7: Secondary risk | H7: Market Risk | I7: Time Series | J7: Effective hedging | K7: Preventive | M7: Daily | N7: Committe or Board decision | S7: N/A | T7: N/A | U7: Medium | V7: 3 | W7: Moderate | X7: 3
E8: N/A | F8: N/A | G8: Key risk | H8: Health and Safety Risk | I8: Once-off | K8: Preventive | N8: System time stemp | S8: N/A | T8: N/A | U8: Probable | V8: 4 | W8: Significant | X8: 4
E9: N/A | F9: N/A | G9: Key risk | H9: Strategic Risk | I9: Once-off | K9: Preventive | N9: System time stemp | S9: N/A | T9: N/A | U9: Very High | V9: 5 | W9: Catastrophic | X9: 5
E10: N/A | F10: N/A | G10: Key risk | H10: Strategic Risk | I10: Periodic | K10: Preventive | M10: Monthly | N10: Meeting minutes | S10: N/A | T10: N/A | U10: N/A | W10: N/A
E11: N/A | F11: N/A | G11: Key risk | H11: Strategic Risk | I11: Once-off | K11: Preventive | N11: System time stemp | S11: N/A | T11: N/A
E12: N/A | F12: N/A | G12: Key risk | H12: Strategic Risk | I12: Once-off | K12: Detective | M12: Once-off | N12: System time stemp | S12: N/A | T12: N/A
E13: N/A | F13: N/A | G13: Key risk | H13: Strategic Risk | I13: Time Series | K13: Detective | N13: Meeting minutes | S13: N/A | T13: N/A
E14: N/A | F14: N/A | G14: Key risk | H14: Strategic Risk | I14: Once-off | K14: Preventive | M14: Per business transaction | N14: Signature | S14: N/A | T14: N/A
E15: N/A | F15: N/A | G15: Key risk | H15: Strategic Risk | I15: Once-off | K15: Preventive | N15: Committe or Board decision | S15: N/A | T15: N/A
A17: Business Objective | B17: Main process | C17: Sub process | D17: Key risk and factors | E17: Likelihood | F17: Impact | G17: Key/Secondary | H17: Risk Category | I17: Data Frequency | J17: Mitigating controls | K17: Nature | L17: Responsibility | M17: Frequency | N17: Evidence | O17: Authoriser | P17: Auditors Recommended Action Plan | Q17: Responsible Person | R17: Agreed Date | S17: Likelihood | T17: Impact | U17: Improbable | V17: 1 | W17: Negligible | X17: 1 | Y17: Link to Dashboard
D18: Project failure and financial losses | E18: Very High | F18: Catastrophic | G18: Key risk | H18: Strategic Risk | I18: Periodic | J18: Feasibility studies, Capital investment decisions supported by discounted cash flow analysis. | K18: Preventive | L18: CFO | M18: Per business transaction | N18: Committe or Board decision | O18: Board | P18: Projects should be grouped according to nature and size of investment. Managed through project management conrtols. Feasibility studies and discounted cash flow analysis should be in place and thoroughly documented and rigourously followed. | Q18: CFO, CEO AND the Board | S18: Probable | T18: Significant | U18: Low | V18: 2 | W18: Lower | X18: 2
E19: N/A | F19: N/A | G19: Secondary risk | H19: Environmental Risk | I19: Time Series | K19: Preventive | N19: Meeting minutes | S19: N/A | T19: N/A | U19: Medium | V19: 3 | W19: Moderate | X19: 3
E20: N/A | F20: N/A | G20: Secondary risk | H20: Strategic Risk | I20: Once-off | K20: Preventive | N20: System time stemp | S20: N/A | T20: N/A | U20: Probable | V20: 4 | W20: Significant | X20: 4
E21: N/A | F21: N/A | G21: Key risk | H21: Strategic Risk | I21: Once-off | K21: Preventive | N21: System time stemp | S21: N/A | T21: N/A | U21: Very High | V21: 5 | W21: Catastrophic | X21: 5
E22: N/A | F22: N/A | G22: Key risk | H22: Strategic Risk | I22: Periodic | K22: Preventive | N22: Meeting minutes | S22: N/A | T22: N/A
E23: N/A | F23: N/A | G23: Key risk | H23: Strategic Risk | I23: Once-off | K23: Preventive | N23: System time stemp | S23: N/A | T23: N/A
E24: N/A | F24: N/A | G24: Key risk | H24: Strategic Risk | I24: Once-off | K24: Preventive | M24: Once-off | N24: System time stemp | S24: N/A | T24: N/A
E25: N/A | F25: N/A | G25: Key risk | H25: Strategic Risk | I25: Time Series | K25: Preventive | N25: Meeting minutes | S25: N/A | T25: N/A
E26: N/A | F26: N/A | G26: Key risk | H26: Strategic Risk | I26: Once-off | K26: Preventive | N26: Signature | S26: N/A | T26: N/A
E27: N/A | F27: N/A | G27: Key risk | H27: Strategic Risk | I27: Once-off | K27: Preventive | N27: Committe or Board decision | S27: N/A | T27: N/A
A29: Business Objective | B29: Main process | C29: Sub process | D29: Key risk and factors | E29: Likelihood | F29: Impact | G29: Key/Secondary | H29: Risk Category | I29: Data Frequency | J29: Mitigating controls | K29: Nature | L29: Responsibility | M29: Frequency | N29: Evidence | O29: Authoriser | P29: Auditors Recommended Action Plan | Q29: Responsible Person | R29: Agreed Date | S29: Likelihood | T29: Impact | U29: Improbable | V29: 1 | W29: Negligible | X29: 1 | Y29: Link to Dashboard
E30: Low | F30: Lower | G30: Key risk | H30: Reputational Risk | I30: Once-off | K30: Preventive | M30: Per business transaction | N30: Meeting minutes | S30: Medium | T30: Moderate | U30: Low | V30: 2 | W30: Lower | X30: 2
E31: N/A | F31: Catastrophic | G31: Secondary risk | H31: Strategic Risk | I31: Once-off | K31: Preventive | N31: Meeting minutes | S31: N/A | T31: N/A | U31: Medium | V31: 3 | W31: Moderate | X31: 3
E32: N/A | F32: N/A | G32: Key risk | H32: Strategic Risk | I32: Once-off | K32: Preventive | N32: System time stemp | S32: N/A | T32: N/A | U32: Probable | V32: 4 | W32: Significant | X32: 4 | Z32: original | AC32: adjusted
E33: N/A | F33: N/A | G33: Key risk | H33: Strategic Risk | I33: Once-off | K33: Preventive | N33: System time stemp | S33: N/A | T33: N/A | U33: Very High | V33: 5 | W33: Catastrophic | X33: 5 | Z33: =E6 -> Very High | AA33: =F6 -> Catastrophic | AB33: 1 | AC33: =S6 -> Medium | AD33: =T6 -> Moderate
E34: N/A | F34: N/A | G34: Key risk | H34: Strategic Risk | I34: Once-off | K34: Preventive | N34: Meeting minutes | S34: N/A | T34: N/A | Z34: =E18 -> Very High | AA34: =F18 -> Catastrophic | AB34: 2 | AC34: =S18 -> Probable | AD34: =T18 -> Significant
E35: N/A | F35: N/A | G35: Key risk | H35: Strategic Risk | I35: Once-off | K35: Preventive | N35: System time stemp | S35: N/A | T35: N/A | Z35: =E30 -> Low | AA35: =F30 -> Lower | AB35: 3 | AC35: =S30 -> Medium | AD35: =T30 -> Moderate
E36: N/A | F36: N/A | G36: Key risk | H36: Strategic Risk | I36: Once-off | K36: Preventive | M36: Once-off | N36: System time stemp | S36: N/A | T36: N/A | Z36: =E42 -> Medium | AA36: =F42 -> Significant | AB36: 4 | AC36: =S42 -> Low | AD36: =T42 -> Moderate
E37: N/A | F37: N/A | G37: Key risk | H37: Strategic Risk | I37: Once-off | K37: Preventive | N37: Meeting minutes | S37: N/A | T37: N/A | Z37: =E54 -> Probable | AA37: =F54 -> Significant | AB37: 5 | AC37: =S54 -> Medium | AD37: =T54 -> Moderate
E38: N/A | F38: N/A | G38: Key risk | H38: Strategic Risk | I38: Once-off | K38: Preventive | N38: Signature | S38: N/A | T38: N/A | Z38: =S66 -> Improbable | AA38: =T66 -> Lower | AB38: 6 | AC38: =S66 -> Improbable | AD38: =T66 -> Lower
E39: N/A | F39: N/A | G39: Key risk | H39: Strategic Risk | I39: Once-off | K39: Preventive | N39: Committe or Board decision | S39: N/A | T39: N/A | Z39: =E78 -> Probable | AA39: =F78 -> Catastrophic | AB39: 7 | AC39: =S78 -> Medium | AD39: =T67 -> N/A
Z40: =E90 -> Probable | AA40: =F90 -> Significant | AB40: 8 | AC40: =S90 -> Medium | AD40: =T90 -> Moderate
A41: Business Objective | B41: Main process | C41: Sub process | D41: Key risk and factors | E41: Likelihood | F41: Impact | G41: Key/Secondary | H41: Risk Category | I41: Data Frequency | J41: Mitigating controls | K41: Nature | L41: Responsibility | M41: Frequency | N41: Evidence | O41: Authoriser | P41: Auditors Recommended Action Plan | Q41: Responsible Person | R41: Agreed Date | S41: Likelihood | T41: Impact | U41: Improbable | V41: 1 | W41: Negligible | X41: 1 | Y41: Link to Dashboard | Z41: =E102 -> Very High | AA41: =F102 -> Catastrophic | AB41: 9 | AC41: =S102 -> Low | AD41: =T102 -> Significant
E42: Medium | F42: Significant | G42: Key risk | H42: Strategic Risk | I42: Once-off | K42: Preventive | M42: Per business transaction | N42: Meeting minutes | S42: Low | T42: Moderate | U42: Low | V42: 2 | W42: Lower | X42: 2 | Z42: =E114 -> Probable | AA42: =F114 -> Catastrophic | AB42: 10 | AC42: =S114 -> Low | AD42: =T114 -> Moderate
...

Sheet HeatMap
A1: RISK PROFILE
C3: Original Assessment | K3: Adjusted Assessment
A5: Impact | B5: Catastrophic | C5: =IF(COUNTIFS(Main!$Z$33:$Z$42,HeatMap!C$10,Main!$AA$33:$AA$42,HeatMap!$B5)=0,"",COUNTIFS(Main!$Z$33:$Z$42,HeatMap!C$10,Main!$AA$33:$AA$42,HeatMap!$B5)) | D5: =IF(COUNTIFS(Main!$Z$33:$Z$42,HeatMap!D$10,Main!$AA$33:$AA$42,HeatMap!$B5)=0,"",COUNTIFS(Main!$Z$33:$Z$42,HeatMap!D$10,Main!$AA$33:$AA$42,HeatMap!$B5)) | E5: =IF(COUNTIFS(Main!$Z$33:$Z$42,HeatMap!E$10,Main!$AA$33:$AA$42,HeatMap!$B5)=0,"",COUNTIFS(Main!$Z$33:$Z$42,HeatMap!E$10,Main!$AA$33:$AA$42,HeatMap!$B5)) | F5: =IF(COUNTIFS(Main!$Z$33:$Z$42,HeatMap!F$10,Main!$AA$33:$AA$42,HeatMap!$B5)=0,"",COUNTIFS(Main!$Z$33:$Z$42,HeatMap!F$10,Main!$AA$33:$AA$42,HeatMap!$B5)) -> 2 | G5: =IF(COUNTIFS(Main!$Z$33:$Z$42,HeatMap!G$10,Main!$AA$33:$AA$42,HeatMap!$B5)=0,"",COUNTIFS(Main!$Z$33:$Z$42,HeatMap!G$10,Main!$AA$33:$AA$42,HeatMap!$B5)) -> 3 | I5: Impact | J5: Catastrophic | K5: =IF(COUNTIFS(Main!$AC$33:$AC$42,K$10,Main!$AD$33:$AD$42,HeatMap!$J5)=0,"",COUNTIFS(Main!$AC$33:$AC$42,K$10,Main!$AD$33:$AD$42,HeatMap!$J5)) | L5: =IF(COUNTIFS(Main!$AC$33:$AC$42,L$10,Main!$AD$33:$AD$42,HeatMap!$J5)=0,"",COUNTIFS(Main!$AC$33:$AC$42,L$10,Main!$AD$33:$AD$42,HeatMap!$J5)) | M5: =IF(COUNTIFS(Main!$AC$33:$AC$42,M$10,Main!$AD$33:$AD$42,HeatMap!$J5)=0,"",COUNTIFS(Main!$AC$33:$AC$42,M$10,Main!$AD$33:$AD$42,HeatMap!$J5)) | N5: =IF(COUNTIFS(Main!$AC$33:$AC$42,N$10,Main!$AD$33:$AD$42,HeatMap!$J5)=0,"",COUNTIFS(Main!$AC$33:$AC$42,N$10,Main!$AD$33:$AD$42,HeatMap!$J5)) | O5: =IF(COUNTIFS(Main!$AC$33:$AC$42,O$10,Main!$AD$33:$AD$42,HeatMap!$J5)=0,"",COUNTIFS(Main!$AC$33:$AC$42,O$10,Main!$AD$33:$AD$42,HeatMap!$J5))
B6: Significant | C6: =IF(COUNTIFS(Main!$Z$33:$Z$42,HeatMap!C$10,Main!$AA$33:$AA$42,HeatMap!$B6)=0,"",COUNTIFS(Main!$Z$33:$Z$42,HeatMap!C$10,Main!$AA$33:$AA$42,HeatMap!$B6)) | D6: =IF(COUNTIFS(Main!$Z$33:$Z$42,HeatMap!D$10,Main!$AA$33:$AA$42,HeatMap!$B6)=0,"",COUNTIFS(Main!$Z$33:$Z$42,HeatMap!D$10,Main!$AA$33:$AA$42,HeatMap!$B6)) | E6: =IF(COUNTIFS(Main!$Z$33:$Z$42,HeatMap!E$10,Main!$AA$33:$AA$42,HeatMap!$B6)=0,"",COUNTIFS(Main!$Z$33:$Z$42,HeatMap!E$10,Main!$AA$33:$AA$42,HeatMap!$B6)) -> 1 | F6: =IF(COUNTIFS(Main!$Z$33:$Z$42,HeatMap!F$10,Main!$AA$33:$AA$42,HeatMap!$B6)=0,"",COUNTIFS(Main!$Z$33:$Z$42,HeatMap!F$10,Main!$AA$33:$AA$42,HeatMap!$B6)) -> 2 | G6: =IF(COUNTIFS(Main!$Z$33:$Z$42,HeatMap!G$10,Main!$AA$33:$AA$42,HeatMap!$B6)=0,"",COUNTIFS(Main!$Z$33:$Z$42,HeatMap!G$10,Main!$AA$33:$AA$42,HeatMap!$B6)) | J6: Significant | K6: =IF(COUNTIFS(Main!$AC$33:$AC$42,K$10,Main!$AD$33:$AD$42,HeatMap!$J6)=0,"",COUNTIFS(Main!$AC$33:$AC$42,K$10,Main!$AD$33:$AD$42,HeatMap!$J6)) | L6: =IF(COUNTIFS(Main!$AC$33:$AC$42,L$10,Main!$AD$33:$AD$42,HeatMap!$J6)=0,"",COUNTIFS(Main!$AC$33:$AC$42,L$10,Main!$AD$33:$AD$42,HeatMap!$J6)) -> 1 | M6: =IF(COUNTIFS(Main!$AC$33:$AC$42,M$10,Main!$AD$33:$AD$42,HeatMap!$J6)=0,"",COUNTIFS(Main!$AC$33:$AC$42,M$10,Main!$AD$33:$AD$42,HeatMap!$J6)) | N6: =IF(COUNTIFS(Main!$AC$33:$AC$42,N$10,Main!$AD$33:$AD$42,HeatMap!$J6)=0,"",COUNTIFS(Main!$AC$33:$AC$42,N$10,Main!$AD$33:$AD$42,HeatMap!$J6)) -> 1 | O6: =IF(COUNTIFS(Main!$AC$33:$AC$42,O$10,Main!$AD$33:$AD$42,HeatMap!$J6)=0,"",COUNTIFS(Main!$AC$33:$AC$42,O$10,Main!$AD$33:$AD$42,HeatMap!$J6))
B7: Moderate | C7: =IF(COUNTIFS(Main!$Z$33:$Z$42,HeatMap!C$10,Main!$AA$33:$AA$42,HeatMap!$B7)=0,"",COUNTIFS(Main!$Z$33:$Z$42,HeatMap!C$10,Main!$AA$33:$AA$42,HeatMap!$B7)) | D7: =IF(COUNTIFS(Main!$Z$33:$Z$42,HeatMap!D$10,Main!$AA$33:$AA$42,HeatMap!$B7)=0,"",COUNTIFS(Main!$Z$33:$Z$42,HeatMap!D$10,Main!$AA$33:$AA$42,HeatMap!$B7)) | E7: =IF(COUNTIFS(Main!$Z$33:$Z$42,HeatMap!E$10,Main!$AA$33:$AA$42,HeatMap!$B7)=0,"",COUNTIFS(Main!$Z$33:$Z$42,HeatMap!E$10,Main!$AA$33:$AA$42,HeatMap!$B7)) | F7: =IF(COUNTIFS(Main!$Z$33:$Z$42,HeatMap!F$10,Main!$AA$33:$AA$42,HeatMap!$B7)=0,"",COUNTIFS(Main!$Z$33:$Z$42,HeatMap!F$10,Main!$AA$33:$AA$42,HeatMap!$B7)) | G7: =IF(COUNTIFS(Main!$Z$33:$Z$42,HeatMap!G$10,Main!$AA$33:$AA$42,HeatMap!$B7)=0,"",COUNTIFS(Main!$Z$33:$Z$42,HeatMap!G$10,Main!$AA$33:$AA$42,HeatMap!$B7)) | J7: Moderate | K7: =IF(COUNTIFS(Main!$AC$33:$AC$42,K$10,Main!$AD$33:$AD$42,HeatMap!$J7)=0,"",COUNTIFS(Main!$AC$33:$AC$42,K$10,Main!$AD$33:$AD$42,HeatMap!$J7)) | L7: =IF(COUNTIFS(Main!$AC$33:$AC$42,L$10,Main!$AD$33:$AD$42,HeatMap!$J7)=0,"",COUNTIFS(Main!$AC$33:$AC$42,L$10,Main!$AD$33:$AD$42,HeatMap!$J7)) -> 2 | M7: =IF(COUNTIFS(Main!$AC$33:$AC$42,M$10,Main!$AD$33:$AD$42,HeatMap!$J7)=0,"",COUNTIFS(Main!$AC$33:$AC$42,M$10,Main!$AD$33:$AD$42,HeatMap!$J7)) -> 4 | N7: =IF(COUNTIFS(Main!$AC$33:$AC$42,N$10,Main!$AD$33:$AD$42,HeatMap!$J7)=0,"",COUNTIFS(Main!$AC$33:$AC$42,N$10,Main!$AD$33:$AD$42,HeatMap!$J7)) | O7: =IF(COUNTIFS(Main!$AC$33:$AC$42,O$10,Main!$AD$33:$AD$42,HeatMap!$J7)=0,"",COUNTIFS(Main!$AC$33:$AC$42,O$10,Main!$AD$33:$AD$42,HeatMap!$J7))
B8: Lower | C8: =IF(COUNTIFS(Main!$Z$33:$Z$42,HeatMap!C$10,Main!$AA$33:$AA$42,HeatMap!$B8)=0,"",COUNTIFS(Main!$Z$33:$Z$42,HeatMap!C$10,Main!$AA$33:$AA$42,HeatMap!$B8)) -> 1 | D8: =IF(COUNTIFS(Main!$Z$33:$Z$42,HeatMap!D$10,Main!$AA$33:$AA$42,HeatMap!$B8)=0,"",COUNTIFS(Main!$Z$33:$Z$42,HeatMap!D$10,Main!$AA$33:$AA$42,HeatMap!$B8)) -> 1 | E8: =IF(COUNTIFS(Main!$Z$33:$Z$42,HeatMap!E$10,Main!$AA$33:$AA$42,HeatMap!$B8)=0,"",COUNTIFS(Main!$Z$33:$Z$42,HeatMap!E$10,Main!$AA$33:$AA$42,HeatMap!$B8)) | F8: =IF(COUNTIFS(Main!$Z$33:$Z$42,HeatMap!F$10,Main!$AA$33:$AA$42,HeatMap!$B8)=0,"",COUNTIFS(Main!$Z$33:$Z$42,HeatMap!F$10,Main!$AA$33:$AA$42,HeatMap!$B8)) | G8: =IF(COUNTIFS(Main!$Z$33:$Z$42,HeatMap!G$10,Main!$AA$33:$AA$42,HeatMap!$B8)=0,"",COUNTIFS(Main!$Z$33:$Z$42,HeatMap!G$10,Main!$AA$33:$AA$42,HeatMap!$B8)) | J8: Lower | K8: =IF(COUNTIFS(Main!$AC$33:$AC$42,K$10,Main!$AD$33:$AD$42,HeatMap!$J8)=0,"",COUNTIFS(Main!$AC$33:$AC$42,K$10,Main!$AD$33:$AD$42,HeatMap!$J8)) -> 1 | L8: =IF(COUNTIFS(Main!$AC$33:$AC$42,L$10,Main!$AD$33:$AD$42,HeatMap!$J8)=0,"",COUNTIFS(Main!$AC$33:$AC$42,L$10,Main!$AD$33:$AD$42,HeatMap!$J8)) | M8: =IF(COUNTIFS(Main!$AC$33:$AC$42,M$10,Main!$AD$33:$AD$42,HeatMap!$J8)=0,"",COUNTIFS(Main!$AC$33:$AC$42,M$10,Main!$AD$33:$AD$42,HeatMap!$J8)) | N8: =IF(COUNTIFS(Main!$AC$33:$AC$42,N$10,Main!$AD$33:$AD$42,HeatMap!$J8)=0,"",COUNTIFS(Main!$AC$33:$AC$42,N$10,Main!$AD$33:$AD$42,HeatMap!$J8)) | O8: =IF(COUNTIFS(Main!$AC$33:$AC$42,O$10,Main!$AD$33:$AD$42,HeatMap!$J8)=0,"",COUNTIFS(Main!$AC$33:$AC$42,O$10,Main!$AD$33:$AD$42,HeatMap!$J8))
B9: Negligible | C9: =IF(COUNTIFS(Main!$Z$33:$Z$42,HeatMap!C$10,Main!$AA$33:$AA$42,HeatMap!$B9)=0,"",COUNTIFS(Main!$Z$33:$Z$42,HeatMap!C$10,Main!$AA$33:$AA$42,HeatMap!$B9)) | D9: =IF(COUNTIFS(Main!$Z$33:$Z$42,HeatMap!D$10,Main!$AA$33:$AA$42,HeatMap!$B9)=0,"",COUNTIFS(Main!$Z$33:$Z$42,HeatMap!D$10,Main!$AA$33:$AA$42,HeatMap!$B9)) | E9: =IF(COUNTIFS(Main!$Z$33:$Z$42,HeatMap!E$10,Main!$AA$33:$AA$42,HeatMap!$B9)=0,"",COUNTIFS(Main!$Z$33:$Z$42,HeatMap!E$10,Main!$AA$33:$AA$42,HeatMap!$B9)) | F9: =IF(COUNTIFS(Main!$Z$33:$Z$42,HeatMap!F$10,Main!$AA$33:$AA$42,HeatMap!$B9)=0,"",COUNTIFS(Main!$Z$33:$Z$42,HeatMap!F$10,Main!$AA$33:$AA$42,HeatMap!$B9)) | G9: =IF(COUNTIFS(Main!$Z$33:$Z$42,HeatMap!G$10,Main!$AA$33:$AA$42,HeatMap!$B9)=0,"",COUNTIFS(Main!$Z$33:$Z$42,HeatMap!G$10,Main!$AA$33:$AA$42,HeatMap!$B9)) | J9: Negligible | K9: =IF(COUNTIFS(Main!$AC$33:$AC$42,K$10,Main!$AD$33:$AD$42,HeatMap!$J9)=0,"",COUNTIFS(Main!$AC$33:$AC$42,K$10,Main!$AD$33:$AD$42,HeatMap!$J9)) | L9: =IF(COUNTIFS(Main!$AC$33:$AC$42,L$10,Main!$AD$33:$AD$42,HeatMap!$J9)=0,"",COUNTIFS(Main!$AC$33:$AC$42,L$10,Main!$AD$33:$AD$42,HeatMap!$J9)) | M9: =IF(COUNTIFS(Main!$AC$33:$AC$42,M$10,Main!$AD$33:$AD$42,HeatMap!$J9)=0,"",COUNTIFS(Main!$AC$33:$AC$42,M$10,Main!$AD$33:$AD$42,HeatMap!$J9)) | N9: =IF(COUNTIFS(Main!$AC$33:$AC$42,N$10,Main!$AD$33:$AD$42,HeatMap!$J9)=0,"",COUNTIFS(Main!$AC$33:$AC$42,N$10,Main!$AD$33:$AD$42,HeatMap!$J9)) | O9: =IF(COUNTIFS(Main!$AC$33:$AC$42,O$10,Main!$AD$33:$AD$42,HeatMap!$J9)=0,"",COUNTIFS(Main!$AC$33:$AC$42,O$10,Main!$AD$33:$AD$42,HeatMap!$J9))
C10: Improbable | D10: Low | E10: Medium | F10: Probable | G10: Very High | K10: Improbable | L10: Low | M10: Medium | N10: Probable | O10: Very High
C11: Likelihood | K11: Likelihood

Sheet OperationalRisk Dashboard
A2: Business Objective | B2: Main process | C2: Sub process | D2: Source | E2: Loss Frequency | F2: Number of Loss Events | G2: Probability | H2: Loss Amount | I2: Risk measurement | J2: VAR | K2: Single VAR(possible loss) | L2: Cumulative VAR (Severity) | N2: Mean
C3: Internal Fraud | D3: People | E3: Annually | F3: 1 | G3: =POISSON(F3,N3,FALSE) -> 0.36787944 | H3: 900000 | I3: Operational VAR | J3: =G3*_xlfn.NORM.S.INV(1-$M$4)*H3 -> -544597.05 | K3: =J3 -> -544597.05 | M3: Confidence level | N3: {=_xlfn.IFS(E3="Daily",F3/252,E3="Weekly",F3/52,E3="Monthly",F3/12,E3="Quarterly",F3/4,E3="Annually",1)} -> 1
G4: =POISSON(F3,N3,TRUE) -> 0.73575888 | J4: =G4*_xlfn.NORM.S.INV(1-$M$4)*H3 -> -1089194.1 | L4: =J4 -> -1089194.1 | M4: 0.95
C9: Employment practices | D9: People | E9: Annually | F9: 4 | G9: =POISSON(F9,N9,FALSE) -> 0.01532831 | H9: 250000 | I9: Operational VAR | J9: =G9*_xlfn.NORM.S.INV(1-$M$4)*H9 -> -6303.2066 | K9: =J9 -> -6303.2066 | N9: {=_xlfn.IFS(E9="Daily",F9/252,E9="Weekly",F9/52,E9="Monthly",F9/12,E9="Quarterly",F9/4,E9="Annually",1)} -> 1
G10: =POISSON(F9,N9,TRUE) -> 0.99634015 | J10: =G10*_xlfn.NORM.S.INV(1-$M$4)*H9 -> -409708.43 | L10: =J10 -> -409708.43
C16: Clients, products and business practices | D16: External Events | E16: Quarterly | F16: 2 | G16: =POISSON(F16,N16,FALSE) -> 0.075816332 | H16: 500000 | I16: Operational VAR | J16: =G16*_xlfn.NORM.S.INV(1-$M$4)*H16 -> -62353.385 | K16: =J16 -> -62353.385 | N16: {=_xlfn.IFS(E16="Daily",F16/252,E16="Weekly",F16/52,E16="Monthly",F16/12,E16="Quarterly",F16/4,E16="Annually",1)} -> 0.5
G17: =POISSON(F16,N16,TRUE) -> 0.98561232 | J17: =G17*_xlfn.NORM.S.INV(1-$M$4)*H16 -> -810594 | L17: =J17 -> -810594
C22: Clients, products and business practices | D22: External Events | E22: Annually | F22: 2 | G22: =POISSON(F22,N22,FALSE) -> 0.18393972 | H22: 500000 | I22: Operational VAR | J22: =G22*_xlfn.NORM.S.INV(1-$M$4)*H22 -> -151276.96 | K22: =J22 -> -151276.96 | N22: {=_xlfn.IFS(E22="Daily",F22/252,E22="Weekly",F22/52,E22="Monthly",F22/12,E22="Quarterly",F22/4,E22="Annually",1)} -> 1
G23: =POISSON(F22,N22,TRUE) -> 0.9196986 | J23: =G23*_xlfn.NORM.S.INV(1-$M$4)*H22 -> -756384.79 | L23: =J23 -> -756384.79
C28: Business disruptions and system failures | D28: Systems | E28: Daily | F28: 1 | G28: =POISSON(F28,N28,FALSE) -> 0.0039525381 | H28: 500000 | I28: Operational VAR | J28: =G28*_xlfn.NORM.S.INV(1-$M$4)*H28 -> -3250.6733 | K28: =J28 -> -3250.6733 | N28: {=_xlfn.IFS(E28="Daily",F28/252,E28="Weekly",F28/52,E28="Monthly",F28/12,E28="Quarterly",F28/4,E28="Annually",1)} -> 0.003968254
G29: =POISSON(F28,N28,TRUE) -> 0.99999215 | J29: =G29*_xlfn.NORM.S.INV(1-$M$4)*H28 -> -822420.36 | L29: =J29 -> -822420.36
C34: Execution, delivery and process management | D34: Systems | E34: Monthly | F34: 2 | G34: =POISSON(F34,N34,FALSE) -> 0.011756691 | H34: 500000 | I34: Operational VAR | J34: =G34*_xlfn.NORM.S.INV(1-$M$4)*H34 -> -9669.0176 | K34: =J34 -> -9669.0176 | N34: {=_xlfn.IFS(E34="Daily",F34/252,E34="Weekly",F34/52,E34="Monthly",F34/12,E34="Quarterly",F34/4,E34="Annually",1)} -> 0.16666667
G35: =POISSON(F34,N34,TRUE) -> 0.9993187 | J35: =G35*_xlfn.NORM.S.INV(1-$M$4)*H34 -> -821866.5 | L35: =J35 -> -821866.5
C39: Total | H39: =SUM(H3:H37) -> 3150000 | K39: =SUM(K3:K37) -> -777450.29 | L39: =SUM(L3:L37) -> -4710168.2

Sheet MarketRisk Dashboard
A2: Key risk and factors | B2: Likelihood | C2: Impact | D2: Key/Secondary | E2: Risk Category | F2: Data Frequency | G2: Mitigating controls | H2: Nature | I2: Responsibility | J2: Frequency | K2: Evidence | L2: Authoriser | M2: Auditors Recommended Action Plan | N2: Responsible Person | O2: Agreed Date | P2: Likelihood | Q2: Impact
A3: =Main!D6 -> Negative returns on the share price | B3: =Main!E6 -> Very High | C3: =Main!F6 -> Catastrophic | D3: =Main!G6 -> Key risk | E3: =Main!H6 -> Strategic Risk | F3: =Main!I6 -> Time Series | G3: =Main!J6 -> Effective hedging | H3: =Main!K6 -> Preventive | ... K3: =Main!N6 -> Committe or Board decision | N3: =Main!Q6 -> 0 | O3: =Main!R6 -> 0 | P3: =Main!S6 -> Medium | Q3: =Main!T6 -> Moderate
B4: Share price (ZAR) | I4: Exchange rate - USDZAR
D17: Column1 | E17: Column2 | F17: Column3 | G17: Column4 | H17: Column5
D18: Based on Capital of e.g ZAR 200,000,000.00
D19: Daily VaR at 95.0% confidence level: -0.0391
D20: Daily CVaR at 95.0% confidence level: -0.0571
D21: Potential Capital Loss based on VAR at 95.0% confidence level: ZAR-46,870,023.14
D22: Potential Capital Loss based on CVAR at 95.0% confidence level: ZAR-68,461,203.80
D25: Returns went below 10% 4 times in history.
D31: Column1 | E31: Column2 | F31: Column3 | G31: Column4 | H31: Column5
D32: Negative skewness is observed with returns dropping below 10%
D33: Negative skewness confirms the frequency of negative returns than postive ones
D34: High kurtosis is observed and depicted by fat-tails confirming a departure from normality
D42: Recommendation
D43: Implement Data Science techniques to regularly monitor the performance of share capital returns and investment portfolios.
D44: Risk measurement should form part of the discussions at various steering committees.
D45: Ensure that the share price is within the Index beta (FTSE ALL Share) and the Metals Sector Beta as an indicator of risk.
